<robot name="simple_biped">
  <link name="base_link">
    <inertial>
      <mass value="1"/>
      <inertia ixx="1" iyy="1" izz="1"/>
    </inertial>
    <visual>
      <geometry><box size="0.2 0.2 0.2"/></geometry>
    </visual>
  </link>

  <joint name="hip_joint" type="revolute">
    <parent link="base_link"/>
    <child link="left_leg"/>
    <origin xyz="0 0 -0.1" rpy="0 0 0"/>
    <axis xyz="1 0 0"/>
    <limit lower="-1.57" upper="1.57" effort="10" velocity="1"/>
  </joint>

  <link name="left_leg">
    <visual>
      <geometry><box size="0.1 0.1 0.3"/></geometry>
    </visual>
  </link>
</robot>
