<?xml version="1.0"?>
<robot name="biped_with_knees">

  <!-- Torso -->
  <link name="torso">
    <visual>
      <geometry>
        <box size="0.2 0.1 0.3"/>
      </geometry>
      <origin xyz="0 0 0" rpy="0 0 0"/>
      <material name="gray">
        <color rgba="0.6 0.6 0.6 1"/>
      </material>
    </visual>
    <collision>
      <geometry>
        <box size="0.2 0.1 0.3"/>
      </geometry>
    </collision>
    <inertial>
      <mass value="5.0"/>
      <inertia ixx="0.05" ixy="0" ixz="0" iyy="0.05" iyz="0" izz="0.05"/>
    </inertial>
  </link>

  <!-- Upper and lower legs (left) -->
  <link name="left_upper_leg">
    <visual>
      <geometry>
        <cylinder length="0.3" radius="0.05"/>
      </geometry>
      <origin xyz="0 0 -0.15" rpy="0 0 0"/>
      <material name="blue">
        <color rgba="0 0 1 1"/>
      </material>
    </visual>
    <collision>
      <geometry>
        <cylinder length="0.3" radius="0.05"/>
      </geometry>
      <origin xyz="0 0 -0.15" rpy="0 0 0"/>
    </collision>
    <inertial>
      <mass value="1.5"/>
      <inertia ixx="0.01" ixy="0" ixz="0" iyy="0.01" iyz="0" izz="0.01"/>
    </inertial>
  </link>

  <link name="left_lower_leg">
    <visual>
      <geometry>
        <cylinder length="0.3" radius="0.04"/>
      </geometry>
      <origin xyz="0 0 -0.15" rpy="0 0 0"/>
      <material name="cyan">
        <color rgba="0 1 1 1"/>
      </material>
    </visual>
    <collision>
      <geometry>
        <cylinder length="0.3" radius="0.04"/>
      </geometry>
      <origin xyz="0 0 -0.15" rpy="0 0 0"/>
    </collision>
    <inertial>
      <mass value="1.0"/>
      <inertia ixx="0.005" ixy="0" ixz="0" iyy="0.005" iyz="0" izz="0.005"/>
    </inertial>
  </link>

  <!-- Upper and lower legs (right) -->
  <link name="right_upper_leg">
    <visual>
      <geometry>
        <cylinder length="0.3" radius="0.05"/>
      </geometry>
      <origin xyz="0 0 -0.15" rpy="0 0 0"/>
      <material name="red">
        <color rgba="1 0 0 1"/>
      </material>
    </visual>
    <collision>
      <geometry>
        <cylinder length="0.3" radius="0.05"/>
      </geometry>
      <origin xyz="0 0 -0.15" rpy="0 0 0"/>
    </collision>
    <inertial>
      <mass value="1.5"/>
      <inertia ixx="0.01" ixy="0" ixz="0" iyy="0.01" iyz="0" izz="0.01"/>
    </inertial>
  </link>

  <link name="right_lower_leg">
    <visual>
      <geometry>
        <cylinder length="0.3" radius="0.04"/>
      </geometry>
      <origin xyz="0 0 -0.15" rpy="0 0 0"/>
      <material name="pink">
        <color rgba="1 0 1 1"/>
      </material>
    </visual>
    <collision>
      <geometry>
        <cylinder length="0.3" radius="0.04"/>
      </geometry>
      <origin xyz="0 0 -0.15" rpy="0 0 0"/>
    </collision>
    <inertial>
      <mass value="1.0"/>
      <inertia ixx="0.005" ixy="0" ixz="0" iyy="0.005" iyz="0" izz="0.005"/>
    </inertial>
  </link>

  <!-- Joints -->
  <!-- Left hip -->
  <joint name="left_hip_joint" type="revolute">
    <parent link="torso"/>
    <child link="left_upper_leg"/>
    <origin xyz="0.1 0 -0.15" rpy="0 0 0"/>
    <axis xyz="1 0 0"/>
    <limit effort="20" lower="-1.57" upper="1.57" velocity="2.0"/>
  </joint>

  <!-- Left knee -->
  <joint name="left_knee_joint" type="revolute">
    <parent link="left_upper_leg"/>
    <child link="left_lower_leg"/>
    <origin xyz="0 0 -0.3" rpy="0 0 0"/>
    <axis xyz="1 0 0"/>
    <limit effort="20" lower="0" upper="2.0" velocity="2.0"/>
  </joint>

  <!-- Right hip -->
  <joint name="right_hip_joint" type="revolute">
    <parent link="torso"/>
    <child link="right_upper_leg"/>
    <origin xyz="-0.1 0 -0.15" rpy="0 0 0"/>
    <axis xyz="1 0 0"/>
    <limit effort="20" lower="-1.57" upper="1.57" velocity="2.0"/>
  </joint>

  <!-- Right knee -->
  <joint name="right_knee_joint" type="revolute">
    <parent link="right_upper_leg"/>
    <child link="right_lower_leg"/>
    <origin xyz="0 0 -0.3" rpy="0 0 0"/>
    <axis xyz="1 0 0"/>
    <limit effort="20" lower="0" upper="2.0" velocity="2.0"/>
  </joint>

</robot>
