<?xml version="1.0"?>
<robot name="simple_biped">

  <!-- Torso/Hip Link -->
  <link name="torso">
    <visual>
      <geometry>
        <box size="0.2 0.1 0.3"/>
      </geometry>
      <origin xyz="0 0 0" rpy="0 0 0"/>
      <material name="gray">
        <color rgba="0.6 0.6 0.6 1"/>
      </material>
    </visual>
    <collision>
      <geometry>
        <box size="0.2 0.1 0.3"/>
      </geometry>
    </collision>
    <inertial>
      <mass value="5.0"/>
      <inertia ixx="0.05" ixy="0" ixz="0" iyy="0.05" iyz="0" izz="0.05"/>
    </inertial>
  </link>

  <!-- Left Leg -->
  <link name="left_leg">
    <visual>
      <geometry>
        <cylinder length="0.5" radius="0.05"/>
      </geometry>
      <origin xyz="0 0 -0.25" rpy="0 0 0"/>
      <material name="blue">
        <color rgba="0 0 1 1"/>
      </material>
    </visual>
    <collision>
      <geometry>
        <cylinder length="0.5" radius="0.05"/>
      </geometry>
      <origin xyz="0 0 -0.25" rpy="0 0 0"/>
    </collision>
    <inertial>
      <mass value="2.0"/>
      <inertia ixx="0.02" ixy="0" ixz="0" iyy="0.02" iyz="0" izz="0.01"/>
    </inertial>
  </link>

  <!-- Right Leg -->
  <link name="right_leg">
    <visual>
      <geometry>
        <cylinder length="0.5" radius="0.05"/>
      </geometry>
      <origin xyz="0 0 -0.25" rpy="0 0 0"/>
      <material name="red">
        <color rgba="1 0 0 1"/>
      </material>
    </visual>
    <collision>
      <geometry>
        <cylinder length="0.5" radius="0.05"/>
      </geometry>
      <origin xyz="0 0 -0.25" rpy="0 0 0"/>
    </collision>
    <inertial>
      <mass value="2.0"/>
      <inertia ixx="0.02" ixy="0" ixz="0" iyy="0.02" iyz="0" izz="0.01"/>
    </inertial>
  </link>

  <!-- Left Hip Joint -->
  <joint name="left_hip_joint" type="revolute">
    <parent link="torso"/>
    <child link="left_leg"/>
    <origin xyz="0.1 0 -0.15" rpy="0 0 0"/>
    <axis xyz="1 0 0"/>
    <limit effort="20" lower="-1.57" upper="1.57" velocity="2.0"/>
  </joint>

  <!-- Right Hip Joint -->
  <joint name="right_hip_joint" type="revolute">
    <parent link="torso"/>
    <child link="right_leg"/>
    <origin xyz="-0.1 0 -0.15" rpy="0 0 0"/>
    <axis xyz="1 0 0"/>
    <limit effort="20" lower="-1.57" upper="1.57" velocity="2.0"/>
  </joint>

</robot>
